import 'package:dio/dio.dart';
import '../config/app_config.dart';
import 'secure_storage_service.dart';
import 'auth_service.dart';

class ErrorTestService {
  final Dio _dio = AppConfig.dioInstance();

  /// Test invalid credentials
  Future<void> testInvalidCredentials() async {
    print('üß™ Testing invalid credentials...');
    try {
      final response = await _dio.post(
        '${AppConfig.authEndpoint}/login',
        data: {
          'identifier': 'invalid@email.com',
          'password': 'wrongpassword',
        },
      );
      print('‚ùå Expected error but got success: ${response.statusCode}');
    } on DioException catch (e) {
      print('‚úÖ Invalid credentials error caught:');
      print('   Status: ${e.response?.statusCode}');
      print('   Message: ${e.response?.data?['message']}');
      print('   Error Type: ${e.type}');
    } catch (e) {
      print('‚ùå Unexpected error: $e');
    }
  }

  /// Test missing fields
  Future<void> testMissingFields() async {
    print('üß™ Testing missing fields...');
    try {
      final response = await _dio.post(
        '${AppConfig.authEndpoint}/login',
        data: {
          'identifier': 'test@example.com',
          // Missing password
        },
      );
      print('‚ùå Expected error but got success: ${response.statusCode}');
    } on DioException catch (e) {
      print('‚úÖ Missing fields error caught:');
      print('   Status: ${e.response?.statusCode}');
      print('   Message: ${e.response?.data?['message']}');
      print('   Error Type: ${e.type}');
    } catch (e) {
      print('‚ùå Unexpected error: $e');
    }
  }

  /// Test network timeout
  Future<void> testNetworkTimeout() async {
    print('üß™ Testing network timeout...');
    try {
      // Use a non-existent endpoint to simulate timeout
      final response = await _dio.get(
        'https://httpbin.org/delay/10', // 10 second delay
        options: Options(
          sendTimeout: const Duration(seconds: 2),
          receiveTimeout: const Duration(seconds: 2),
        ),
      );
      print('‚ùå Expected timeout but got success: ${response.statusCode}');
    } on DioException catch (e) {
      print('‚úÖ Network timeout error caught:');
      print('   Error Type: ${e.type}');
      print('   Message: ${e.message}');
    } catch (e) {
      print('‚ùå Unexpected error: $e');
    }
  }

  /// Test server error
  Future<void> testServerError() async {
    print('üß™ Testing server error...');
    try {
      final response = await _dio.get('https://httpbin.org/status/500');
      print('‚ùå Expected error but got success: ${response.statusCode}');
    } on DioException catch (e) {
      print('‚úÖ Server error caught:');
      print('   Status: ${e.response?.statusCode}');
      print('   Error Type: ${e.type}');
    } catch (e) {
      print('‚ùå Unexpected error: $e');
    }
  }

  /// Test unauthorized access
  Future<void> testUnauthorizedAccess() async {
    print('üß™ Testing unauthorized access...');
    try {
      // Try to access a protected endpoint without token
      final response = await _dio.get('${AppConfig.authEndpoint}/profile');
      print('‚ùå Expected unauthorized but got success: ${response.statusCode}');
    } on DioException catch (e) {
      print('‚úÖ Unauthorized error caught:');
      print('   Status: ${e.response?.statusCode}');
      print('   Message: ${e.response?.data?['message']}');
      print('   Error Type: ${e.type}');
    } catch (e) {
      print('‚ùå Unexpected error: $e');
    }
  }

  /// Test invalid token
  Future<void> testInvalidToken() async {
    print('üß™ Testing invalid token...');
    try {
      // Save an invalid token
      await SecureStorageService.saveAuthToken('invalid_token_123');
      
      // Try to access a protected endpoint with invalid token
      final response = await _dio.get(
        '${AppConfig.authEndpoint}/profile',
        options: Options(
          headers: {
            'Authorization': 'Bearer invalid_token_123',
          },
        ),
      );
      print('‚ùå Expected invalid token error but got success: ${response.statusCode}');
    } on DioException catch (e) {
      print('‚úÖ Invalid token error caught:');
      print('   Status: ${e.response?.statusCode}');
      print('   Message: ${e.response?.data?['message']}');
      print('   Error Type: ${e.type}');
    } catch (e) {
      print('‚ùå Unexpected error: $e');
    } finally {
      // Clean up
      await SecureStorageService.removeAuthToken();
    }
  }

  /// Test registration with existing email
  Future<void> testDuplicateRegistration() async {
    print('üß™ Testing duplicate registration...');
    try {
      final response = await _dio.post(
        '${AppConfig.authEndpoint}/register',
        data: {
          'name': 'Test User',
          'email': 'hubert@devslab.io', // Already exists
          'phone': '+250788123456',
          'password': 'password123',
          'role': 'owner',
          'permissions': {
            'can_collect': true,
            'can_add_supplier': true,
            'can_view_reports': true,
          },
        },
      );
      print('‚ùå Expected duplicate error but got success: ${response.statusCode}');
    } on DioException catch (e) {
      print('‚úÖ Duplicate registration error caught:');
      print('   Status: ${e.response?.statusCode}');
      print('   Message: ${e.response?.data?['message']}');
      print('   Error Type: ${e.type}');
    } catch (e) {
      print('‚ùå Unexpected error: $e');
    }
  }

  /// Test malformed JSON
  Future<void> testMalformedJson() async {
    print('üß™ Testing malformed JSON...');
    try {
      final response = await _dio.post(
        '${AppConfig.authEndpoint}/login',
        data: 'invalid json string',
        options: Options(
          headers: {
            'Content-Type': 'application/json',
          },
        ),
      );
      print('‚ùå Expected JSON error but got success: ${response.statusCode}');
    } on DioException catch (e) {
      print('‚úÖ Malformed JSON error caught:');
      print('   Error Type: ${e.type}');
      print('   Message: ${e.message}');
    } catch (e) {
      print('‚ùå Unexpected error: $e');
    }
  }

  /// Test all error scenarios
  Future<void> runAllErrorTests() async {
    print('üöÄ Starting comprehensive error handling tests...\n');
    
    await testInvalidCredentials();
    print('');
    
    await testMissingFields();
    print('');
    
    await testNetworkTimeout();
    print('');
    
    await testServerError();
    print('');
    
    await testUnauthorizedAccess();
    print('');
    
    await testInvalidToken();
    print('');
    
    await testDuplicateRegistration();
    print('');
    
    await testMalformedJson();
    print('');
    
    print('‚úÖ All error handling tests completed!');
  }

  /// Test error handling in AuthService
  Future<void> testAuthServiceErrors() async {
    print('üß™ Testing AuthService error handling...');
    
    // Test with invalid credentials
    try {
      final authService = AuthService();
      await authService.login('invalid@email.com', 'wrongpassword');
      print('‚ùå Expected error but got success');
    } catch (e) {
      print('‚úÖ AuthService error handling works:');
      print('   Error: $e');
    }
  }
}
